<mujoco model="follower_arm">
    <default>
        <joint armature="0.01" damping="0.1" limited="true"/>
        <geom conaffinity="1" condim="3" density="100" friction="1 0.5 0.5" margin="0.001" rgba="0.2 0.2 0.8 1"/>
        <!-- MG90S Stall Torque: 0.2 Nm -->
        <position kp="2" forcelimited="true" forcerange="-0.2 0.2"/>
    </default>

    <worldbody>
        <body name="f_base" pos="0 0 0">
            <geom name="f_base_geom" type="cylinder" size="0.03 0.01"/>
            <joint name="f_joint1" type="hinge" axis="0 0 1" range="-170 170"/>
            
            <body name="f_shoulder" pos="0 0 0.02">
                <geom name="f_shoulder_geom" type="box" size="0.015 0.015 0.02"/>
                <joint name="f_joint2" type="hinge" axis="0 1 0" range="-90 90"/>
                
                <body name="f_upper_arm" pos="0 0 0.04">
                    <geom name="f_upper_arm_geom" type="cylinder" size="0.005 0.05" rgba="0.5 0.5 1 1" pos="0 0 0.025"/>
                    <body name="f_elbow" pos="0 0 0.05">
                        <geom name="f_elbow_geom" type="box" size="0.015 0.015 0.01"/>
                        <joint name="f_joint3" type="hinge" axis="0 1 0" range="-120 120"/>
                        
                        <body name="f_forearm" pos="0 0 0.02">
                            <geom name="f_forearm_geom" type="cylinder" size="0.005 0.04" rgba="0.5 0.5 1 1" pos="0 0 0.02"/>
                            <body name="f_wrist" pos="0 0 0.04">
                                <geom name="f_wrist_geom" type="box" size="0.01 0.01 0.01"/>
                                <joint name="f_joint4" type="hinge" axis="0 1 0" range="-90 90"/>
                                
                                <body name="f_wrist_roll" pos="0 0 0.015">
                                    <geom name="f_wrist_roll_geom" type="box" size="0.01 0.01 0.01"/>
                                    <joint name="f_joint5" type="hinge" axis="0 0 1" range="-170 170"/>
                                    
                                    <body name="f_gripper" pos="0 0 0.01">
                                        <geom name="f_gripper_palm" type="box" size="0.02 0.01 0.005" rgba="0.3 0.3 0.3 1"/>
                                        <body name="f_left_finger" pos="-0.015 0 0.01">
                                            <geom name="f_left_finger_geom" type="box" size="0.002 0.005 0.015" rgba="0.1 0.1 0.1 1"/>
                                            <joint name="f_joint6_l" type="hinge" axis="0 1 0" range="0 45"/>
                                        </body>
                                        <body name="f_right_finger" pos="0.015 0 0.01">
                                            <geom name="f_right_finger_geom" type="box" size="0.002 0.005 0.015" rgba="0.1 0.1 0.1 1"/>
                                            <joint name="f_joint6_r" type="hinge" axis="0 -1 0" range="0 45"/>
                                        </body>
                                    </body>
                                </body>
                            </body>
                        </body>
                    </body>
                </body>
            </body>
        </body>
    </worldbody>

    <actuator>
        <position name="f_motor1" joint="f_joint1"/>
        <position name="f_motor2" joint="f_joint2"/>
        <position name="f_motor3" joint="f_joint3"/>
        <position name="f_motor4" joint="f_joint4"/>
        <position name="f_motor5" joint="f_joint5"/>
        <position name="f_motor6" joint="f_joint6_l" kp="5"/>
        <position name="f_motor7" joint="f_joint6_r" kp="5"/>
    </actuator>
</mujoco>
